<robot name="rm" version="1.0">
  <joint name="bevel_pitch" type="revolute">
    <limit lower="-1.57000" upper="1.57000" effort="10.0" velocity="2.0"/>
    <origin rpy="0 0.00000 0" xyz="0.00000 0.00000 0.00000"/>
    <parent link="bevel_link"/>
    <child link="bevel_link_link"/>
    <axis xyz="1.00000 0.00000 0.00000"/>
  </joint>
  <joint name="bevel_roll" type="revolute">
    <limit lower="-1.57000" upper="1.57000" effort="10.0" velocity="2.0"/>
    <origin rpy="0.00000 0.00000 0.00000" xyz="-0.51941 -0.00182 -0.00020"/>
    <parent link="link2_link"/>
    <child link="bevel_link"/>
    <axis xyz="0.00000 1.00000 0.00000"/>
  </joint>
  <joint name="gripper_l" type="prismatic">
    <limit lower="0.00000" upper="0.08000" effort="10.0" velocity="2.0"/>
    <origin rpy="0.00000 0.00000 0.0" xyz="-0.11603 -0.01154 0.00026"/>
    <parent link="bevel_link_link"/>
    <child link="gripperl_link"/>
    <axis xyz="0.00000 -1.00000 0.00000"/>
  </joint>
  <joint name="gripper_r" type="prismatic">
    <limit lower="0.00000" upper="0.08000" effort="10.0" velocity="2.0"/>
    <origin rpy="0.00000 0.00000 0.0" xyz="-0.11612 0.00953 0.00026"/>
    <parent link="bevel_link_link"/>
    <child link="gripperr_link"/>
    <axis xyz="0.00000 1.00000 0.00000"/>
  </joint>
  <joint name="link1" type="revolute">
    <limit lower="-1.10000" upper="0.60000" effort="10.0" velocity="2.0"/>
    <origin rpy="0.00000 0.00000 0.00000" xyz="-0.00009 0.00000 0.11805"/>
    <parent link="swivel_link"/>
    <child link="link1_link"/>
    <axis xyz="0.00000 1.00000 0.00000"/>
  </joint>
  <joint name="link2" type="revolute">
    <limit lower="-1.10000" upper="0.80000" effort="10.0" velocity="2.0"/>
    <origin rpy="0.00000 0.00000 0.00000" xyz="-0.00188 0.00211 0.57968"/>
    <parent link="link1_link"/>
    <child link="link2_link"/>
    <axis xyz="0.00000 1.00000 0.00000"/>
  </joint>
  <joint name="swivel" type="revolute">
    <limit lower="-1.57000" upper="1.57000" effort="10.0" velocity="2.0"/>
    <origin rpy="0.00000 0.00000 0.00000" xyz="0.00009 -0.00000 0.05537"/>
    <parent link="body_link"/>
    <child link="swivel_link"/>
    <axis xyz="0.00000 0.00000 1.00000"/>
  </joint>
  <link name="bevel_link">
    <collision name="bevel_collision_roll">
      <origin rpy="0.0 -0.00000 0.0" xyz="0.00000 -0.00000 0.00000"/>
      <geometry>
        <mesh filename="package://actual_rm_description/meshes/stl/bevel_collision_roll.stl" scale="1.00000 1.00000 1.00000"/>
      </geometry>
    </collision>
    <visual name="bevel_roll">
      <origin rpy="0.0 -0.00000 0.0" xyz="0.00000 -0.00000 -0.00000"/>
      <geometry>
        <mesh filename="package://actual_rm_description/meshes/stl/bevel_roll.stl" scale="1.00000 1.00000 1.00000"/>
      </geometry>
    </visual>
  </link>
  <link name="bevel_link_link">
    <collision name="bevel_collision_pitch">
      <origin rpy="0.00000 0.00000 0.0" xyz="-0.00000 0.00000 0.00000"/>
      <geometry>
        <mesh filename="package://actual_rm_description/meshes/stl/bevel_collision_pitch.stl" scale="1.00000 1.00000 1.00000"/>
      </geometry>
    </collision>
    <visual name="bevel_pitch">
      <origin rpy="0.00000 0.00000 0.0" xyz="-0.00000 0.00000 0.00000"/>
      <geometry>
        <mesh filename="package://actual_rm_description/meshes/stl/bevel_pitch.stl" scale="1.00000 1.00000 1.00000"/>
      </geometry>
    </visual>
  </link>
  <link name="body_link">
    <collision name="body_collision">
      <origin rpy="0.00000 0.00000 0.00000" xyz="0.00000 0.00000 0.00000"/>
      <geometry>
        <mesh filename="package://actual_rm_description/meshes/stl/body_collision.stl" scale="1.00000 1.00000 1.00000"/>
      </geometry>
    </collision>
    <visual name="body">
      <origin rpy="0.00000 0.00000 0.00000" xyz="0.00000 0.00000 0.00000"/>
      <geometry>
        <mesh filename="package://actual_rm_description/meshes/stl/body.stl" scale="1.00000 1.00000 1.00000"/>
      </geometry>
    </visual>
  </link>
  <link name="gripperl_link">
    <collision name="gripperl_collision">
      <origin rpy="0.00000 0.00000 0.00000" xyz="0.00000 -0.00906 0.00000"/>
      <geometry>
        <mesh filename="package://actual_rm_description/meshes/stl/gripperl_collision.stl" scale="1.00000 1.00000 1.00000"/>
      </geometry>
    </collision>
    <visual name="gripperl">
      <origin rpy="0.00000 0.00000 0.00000" xyz="0.00000 -0.00906 0.00000"/>
      <geometry>
        <mesh filename="package://actual_rm_description/meshes/stl/gripperl.stl" scale="1.00000 1.00000 1.00000"/>
      </geometry>
    </visual>
  </link>
  <link name="gripperr_link">
    <collision name="gripperr_collision">
      <origin rpy="0.00000 0.00000 0.00000" xyz="0.00000 0.01059 -0.00000"/>
      <geometry>
        <mesh filename="package://actual_rm_description/meshes/stl/gripperr_collision.stl" scale="1.00000 1.00000 1.00000"/>
      </geometry>
    </collision>
    <visual name="gripperr">
      <origin rpy="0.00000 0.00000 0.00000" xyz="0.00000 0.01059 -0.00000"/>
      <geometry>
        <mesh filename="package://actual_rm_description/meshes/stl/gripperr.stl" scale="1.00000 1.00000 1.00000"/>
      </geometry>
    </visual>
  </link>
  <link name="link1_link">
    <collision name="link1_collision">
      <origin rpy="0.00000 0.00000 0.00000" xyz="0.00000 0.00000 0.00000"/>
      <geometry>
        <mesh filename="package://actual_rm_description/meshes/stl/link1_collision.stl" scale="1.00000 1.00000 1.00000"/>
      </geometry>
    </collision>
    <visual name="link1">
      <origin rpy="0.00000 0.00000 0.00000" xyz="0.00000 0.00000 0.00000"/>
      <geometry>
        <mesh filename="package://actual_rm_description/meshes/stl/link1.stl" scale="1.00000 1.00000 1.00000"/>
      </geometry>
    </visual>
  </link>
  <link name="link2_link">
    <collision name="link2_collision">
      <origin rpy="0.00000 0.00000 0.00000" xyz="0.00000 0.00000 0.00000"/>
      <geometry>
        <mesh filename="package://actual_rm_description/meshes/stl/link2_collision.stl" scale="1.00000 1.00000 1.00000"/>
      </geometry>
    </collision>
    <visual name="link2">
      <origin rpy="0.00000 0.00000 0.00000" xyz="0.00000 0.00000 0.00000"/>
      <geometry>
        <mesh filename="package://actual_rm_description/meshes/stl/link2.stl" scale="1.00000 1.00000 1.00000"/>
      </geometry>
    </visual>
  </link>
  <link name="swivel_link">
    <collision name="swivel_collision">
      <origin rpy="0.00000 0.00000 0.00000" xyz="0.00000 0.00000 0.00000"/>
      <geometry>
        <mesh filename="package://actual_rm_description/meshes/stl/Cube.001.stl" scale="1.00000 1.00000 1.00000"/>
      </geometry>
    </collision>
    <visual name="swivel">
      <origin rpy="0.00000 0.00000 0.00000" xyz="0.00000 0.00000 0.00000"/>
      <geometry>
        <mesh filename="package://actual_rm_description/meshes/stl/swivel.stl" scale="1.00000 1.00000 1.00000"/>
      </geometry>
    </visual>
  </link>
</robot>