<robot name="rm_the_good" version="1.0">

  <!-- JOINTS (unchanged) -->
  <joint name="bevel_pitch" type="revolute">
    <dynamics damping="2.0"/>
    <limit lower="-1.57" upper="1.57" effort="5" velocity="1"/>
    <origin rpy="0 0 0" xyz="-0.52322 -0.00182 -0.00020"/>
    <parent link="link2_link"/>
    <child link="bevel_link"/>
    <axis xyz="0 1 0"/>
  </joint>

  <joint name="bevel_roll" type="revolute">
    <limit lower="-3.14" upper="3.14" effort="5" velocity="1"/>
    <origin rpy="0 0 0" xyz="0 0 0"/>
    <parent link="bevel_link"/>
    <child link="bevel_link.001"/>
    <axis xyz="-1 0 0"/>
  </joint>

  <joint name="gripper_l" type="prismatic">
    <limit lower="0" upper="0.06" effort="0.5" velocity="0.8"/>
    <origin rpy="0 0 0" xyz="-0.11603 -0.01154 -0.00026"/>
    <parent link="bevel_link.001"/>
    <child link="gripperl_link"/>
    <axis xyz="0 -1 0"/>
  </joint>

  <joint name="gripper_r" type="prismatic">
    <limit lower="0" upper="0.06" effort="0.5" velocity="0.8"/>
    <origin rpy="0 0 0" xyz="-0.11612 0.00953 -0.00026"/>
    <parent link="bevel_link.001"/>
    <child link="gripperr_link"/>
    <axis xyz="0 1 0"/>
  </joint>

  <joint name="link1" type="revolute">
    <dynamics damping="2.0"/>
    <limit lower="-1.3" upper="0.4" effort="200" velocity="0.5"/>
    <origin rpy="0 0 0" xyz="0 0.00974 0.135"/>
    <parent link="swivel_link"/>
    <child link="link1_link"/>
    <axis xyz="0 1 0"/>
  </joint>

  <joint name="link2" type="revolute">
    <dynamics damping="2.0"/>
    <limit lower="-1.0" upper="0.7" effort="200" velocity="0.5"/>
    <origin rpy="0 0 0" xyz="0.00206 0.00211 0.57999"/>
    <parent link="link1_link"/>
    <child link="link2_link"/>
    <axis xyz="0 1 0"/>
  </joint>

  <joint name="swivel" type="revolute">
    <dynamics damping="2.0"/>
    <limit lower="-1.57" upper="1.57" effort="200" velocity="0.5"/>
    <origin rpy="0 0 0" xyz="-0.25603 0.00250 0.56163"/>
    <parent link="body_link"/>
    <child link="swivel_link"/>
    <axis xyz="0 0 1"/>
  </joint>

  <!-- LINKS -->

  <!-- NOT FIXED AS REQUESTED -->
  <link name="bevel_link">
    <inertial>
    <origin xyz="0 0 0" rpy="0 0 0"/>
    <mass value="0.1"/>
    <inertia ixx="0.001" iyy="0.001" izz="0.001"
             ixy="0" ixz="0" iyz="0"/>
  </inertial>
  </link>

  <link name="bevel_link.001">
    <inertial>
      <origin xyz="0 0 0" rpy="0 0 0"/>
      <mass value="0.1"/>
      <inertia ixx="0.001" iyy="0.001" izz="0.001" ixy="0" ixz="0" iyz="0"/>
    </inertial>
    <collision>
      <geometry><mesh filename="package://actual_rm_description/meshes/stl/bevel.stl"/></geometry>
    </collision>
    <visual>
      <geometry><mesh filename="package://actual_rm_description/meshes/stl/wwad.stl"/></geometry>
    </visual>
  </link>

  <link name="body_link">
    <inertial>
      <origin xyz="0 0 0" rpy="0 0 0"/>
      <mass value="2.0"/>
      <inertia ixx="0.02" iyy="0.02" izz="0.02" ixy="0" ixz="0" iyz="0"/>
    </inertial>
    <collision>
      <geometry><mesh filename="package://actual_rm_description/meshes/stl/adshag.stl"/></geometry>
    </collision>
    <visual>
      <geometry><mesh filename="package://actual_rm_description/meshes/stl/body.stl"/></geometry>
    </visual>
  </link>

  <link name="gripperl_link">
    <inertial>
      <origin xyz="0 0 0" rpy="0 0 0"/>
      <mass value="0.05"/>
      <inertia ixx="0.0005" iyy="0.0005" izz="0.0005" ixy="0" ixz="0" iyz="0"/>
    </inertial>
    <collision>
      <geometry><mesh filename="package://actual_rm_description/meshes/stl/dsgsdah.stl"/></geometry>
    </collision>
    <visual>
      <geometry><mesh filename="package://actual_rm_description/meshes/stl/awsf.stl"/></geometry>
    </visual>
  </link>

  <link name="gripperr_link">
    <inertial>
      <origin xyz="0 0 0" rpy="0 0 0"/>
      <mass value="0.05"/>
      <inertia ixx="0.0005" iyy="0.0005" izz="0.0005" ixy="0" ixz="0" iyz="0"/>
    </inertial>
    <collision>
      <geometry><mesh filename="package://actual_rm_description/meshes/stl/afws.stl"/></geometry>
    </collision>
    <visual>
      <geometry><mesh filename="package://actual_rm_description/meshes/stl/afsg.stl"/></geometry>
    </visual>
  </link>

  <link name="link1_link">
    <inertial>
      <origin xyz="0 0 0" rpy="0 0 0"/>
      <mass value="1.0"/>
      <inertia ixx="0.01" iyy="0.01" izz="0.01" ixy="0" ixz="0" iyz="0"/>
    </inertial>
    <collision>
      <geometry><mesh filename="package://actual_rm_description/meshes/stl/agsf.stl"/></geometry>
    </collision>
    <visual>
      <geometry><mesh filename="package://actual_rm_description/meshes/stl/link1.stl"/></geometry>
    </visual>
  </link>

  <link name="link2_link">
    <inertial>
      <origin xyz="0 0 0" rpy="0 0 0"/>
      <mass value="1.0"/>
      <inertia ixx="0.01" iyy="0.01" izz="0.01" ixy="0" ixz="0" iyz="0"/>
    </inertial>
    <collision>
      <geometry><mesh filename="package://actual_rm_description/meshes/stl/asgd.stl"/></geometry>
    </collision>
    <visual>
      <geometry><mesh filename="package://actual_rm_description/meshes/stl/link2.stl"/></geometry>
    </visual>
  </link>

  <link name="swivel_link">
    <inertial>
      <origin xyz="0 0 0" rpy="0 0 0"/>
      <mass value="1.0"/>
      <inertia ixx="0.01" iyy="0.01" izz="0.01" ixy="0" ixz="0" iyz="0"/>
    </inertial>
    <collision name="swivel.001">
      <origin rpy="0.00000 0.00000 0.00000" xyz="0.25603 -0.00250 -0.55817"/>
      <geometry>
        <mesh filename="package://actual_rm_description/meshes/stl/aesdg.stl" scale="1.00000 1.00000 1.00000"/>
      </geometry>
    </collision>
    <visual name="swivel">
      <origin rpy="0.00000 0.00000 0.00000" xyz="0.25603 -0.00250 -0.55817"/>
      <geometry>
        <mesh filename="package://actual_rm_description/meshes/stl/swivel.stl" scale="1.00000 1.00000 1.00000"/>
      </geometry>
    </visual>
  </link>


</robot>
