<?xml version="1.0"?>
<robot name="stick_rm">

  <!-- ================= LINKS ================= -->

  <link name="body_link">
    <inertial>
      <mass value="2.0"/>
      <origin xyz="0 0 0"/>
      <inertia ixx="0.02" ixy="0" ixz="0" iyy="0.02" iyz="0" izz="0.02"/>
    </inertial>
    <collision>
      <geometry>
        <mesh filename="package://stick_rm_description/meshes/stl/Cube.017.stl"/>
      </geometry>
    </collision>
    <visual>
      <geometry>
        <mesh filename="package://stick_rm_description/meshes/stl/Cube.010.stl"/>
      </geometry>
    </visual>
  </link>

  <link name="swivel_link">
    <inertial>
      <mass value="1.0"/>
      <origin xyz="0 0 0"/>
      <inertia ixx="0.01" ixy="0" ixz="0" iyy="0.01" iyz="0" izz="0.01"/>
    </inertial>
    <collision>
      <geometry>
        <mesh filename="package://stick_rm_description/meshes/stl/Circle.002.stl" scale="0.12364 0.12364 0.12364"/>
      </geometry>
    </collision>
    <visual>
      <geometry>
        <mesh filename="package://stick_rm_description/meshes/stl/Circle.001.stl" scale="0.12364 0.12364 0.12364"/>
      </geometry>
    </visual>
  </link>

  <link name="link1_link">
    <inertial>
      <mass value="1.0"/>
      <origin xyz="0 0 0"/>
      <inertia ixx="0.01" ixy="0" ixz="0" iyy="0.01" iyz="0" izz="0.01"/>
    </inertial>
    <collision>
      <geometry>
        <mesh filename="package://stick_rm_description/meshes/stl/Cube.016.stl"/>
      </geometry>
    </collision>
    <visual>
      <geometry>
        <mesh filename="package://stick_rm_description/meshes/stl/Cube.003.stl"/>
      </geometry>
    </visual>
  </link>

  <link name="link2_link">
    <inertial>
      <mass value="0.8"/>
      <origin xyz="0 0 0"/>
      <inertia ixx="0.008" ixy="0" ixz="0" iyy="0.008" iyz="0" izz="0.008"/>
    </inertial>
    <collision>
      <geometry>
        <mesh filename="package://stick_rm_description/meshes/stl/Cube.015.stl"/>
      </geometry>
    </collision>
    <visual>
      <geometry>
        <mesh filename="package://stick_rm_description/meshes/stl/Cube.004.stl"/>
      </geometry>
    </visual>
  </link>

  <!-- ================= JOINTS ================= -->

  <joint name="swivel_link_joint" type="revolute">
    <origin xyz="0 0 0.1244" rpy="0 0 0"/>
    <parent link="body_link"/>
    <child link="swivel_link"/>
    <axis xyz="0 0 1"/>
    <limit lower="-1.57" upper="1.57" effort="10" velocity="1.0"/>
  </joint>

  <joint name="link1_link_joint" type="revolute">
    <origin xyz="0 0 0.02551" rpy="0 0 0"/>
    <parent link="swivel_link"/>
    <child link="link1_link"/>
    <axis xyz="1 0 0"/>
    <limit lower="-0.5" upper="1.2" effort="10" velocity="1.0"/>
  </joint>

  <joint name="link2_link_joint" type="revolute">
    <origin xyz="0 -0.025 0.6" rpy="0 0 0"/>
    <parent link="link1_link"/>
    <child link="link2_link"/>
    <axis xyz="1 0 0"/>
    <limit lower="-1.5" upper="1.1" effort="10" velocity="1.0"/>
  </joint>

</robot>
